Workbook

Sheet Start here
A1: Landlord compliance tracker – England
A2: For landlords letting in England. A record-keeping aid, not legal advice. Rules differ in Wales, Scotland and Northern Ireland. Always check the linked gov.uk source; rules change.
A4: 1. Properties: list up to 10 properties (yellow cells).
A5: 2. Compliance: for each property and check, enter the date it was last done (or the expiry date for licences).
A6: Next due and status fill in automatically: red = overdue, amber = due within 60 days, green = OK.
A7: 3. Dashboard: see every overdue and upcoming item at a glance.
A8: 4. Renters' Rights Act: checklist of changes now in force, with sources.
A10: Facts last checked 25 September 2026. Buyers get free updates for 12 months as rules change.

Sheet Dashboard
A1: Dashboard
A3: Overdue | B3: =COUNTIF(Compliance!H2:H101,"OVERDUE")
A4: Missing records | B4: =COUNTIF(Compliance!H2:H101,"Missing")
A5: Due within 60 days | B5: =COUNTIF(Compliance!H2:H101,"Due soon")
A6: OK | B6: =COUNTIF(Compliance!H2:H101,"OK")
A8: Filter the Compliance sheet by Status to see which items need action.
A9: For landlords letting in England. A record-keeping aid, not legal advice. Rules differ in Wales, Scotland and Northern Ireland. Always check the linked gov.uk source; rules change.

Sheet Properties
A1: # | B1: Address | C1: Tenant name(s) | D1: Tenancy start | E1: Deposit scheme + ref | F1: Notes
A2: 1
A3: 2
A4: 3
A5: 4
A6: 5
A7: 6
A8: 7
A9: 8
A10: 9
A11: 10

Sheet Compliance
A1: Property # | B1: Address | C1: Check | D1: Last done / expiry | E1: Interval (months) | F1: Next due | G1: Days left | H1: Status | I1: Rule | J1: Source
A2: 1 | B2: =IF(Properties!B2="","",Properties!B2) | C2: Gas safety check (CP12) | E2: 12 | F2: =IF(D2="","",EDATE(D2,E2)) | G2: =IF(F2="","",F2-TODAY()) | H2: =IF(B2="","",IF(F2="",IF(D2="","Missing","Recorded"),IF(G2<0,"OVERDUE",IF(G2<=60,"Due soon","OK")))) | I2: Every 12 months by a Gas Safe engineer; copy to tenants within 28 days; keep records 2 years. | J2: gov.uk/government/publications/gas-safety-landlords-and-tenants
A3: 1 | B3: =IF(Properties!B2="","",Properties!B2) | C3: Electrical safety report (EICR) | E3: 60 | F3: =IF(D3="","",EDATE(D3,E3)) | G3: =IF(F3="","",F3-TODAY()) | H3: =IF(B3="","",IF(F3="",IF(D3="","Missing","Recorded"),IF(G3<0,"OVERDUE",IF(G3<=60,"Due soon","OK")))) | I3: At least every 5 years by a qualified person; copy to tenants within 28 days. | J3: gov.uk/government/publications/electrical-safety-standards-in-the-private-rented-sector-guidance-for-landlords-tenants-and-local-authorities
A4: 1 | B4: =IF(Properties!B2="","",Properties!B2) | C4: Energy Performance Certificate (EPC) | E4: 120 | F4: =IF(D4="","",EDATE(D4,E4)) | G4: =IF(F4="","",F4-TODAY()) | H4: =IF(B4="","",IF(F4="",IF(D4="","Missing","Recorded"),IF(G4<0,"OVERDUE",IF(G4<=60,"Due soon","OK")))) | I4: Valid 10 years; rating must be E or above to let (unless exempt). | J4: gov.uk/guidance/domestic-private-rented-property-minimum-energy-efficiency-standard-landlord-guidance
A5: 1 | B5: =IF(Properties!B2="","",Properties!B2) | C5: Smoke alarms tested | G5: =IF(F5="","",F5-TODAY()) | H5: =IF(B5="","",IF(F5="",IF(D5="","Missing","Recorded"),IF(G5<0,"OVERDUE",IF(G5<=60,"Due soon","OK")))) | I5: At least one on every storey used as living accommodation; check working on the first day of each tenancy. | J5: gov.uk/government/publications/smoke-and-carbon-monoxide-alarms-explanatory-booklet-for-landlords
A6: 1 | B6: =IF(Properties!B2="","",Properties!B2) | C6: Carbon monoxide alarms tested | G6: =IF(F6="","",F6-TODAY()) | H6: =IF(B6="","",IF(F6="",IF(D6="","Missing","Recorded"),IF(G6<0,"OVERDUE",IF(G6<=60,"Due soon","OK")))) | I6: In any room with a fixed combustion appliance (not gas cookers); check on the first day of each tenancy. | J6: gov.uk/government/publications/smoke-and-carbon-monoxide-alarms-explanatory-booklet-for-landlords
A7: 1 | B7: =IF(Properties!B2="","",Properties!B2) | C7: Deposit protected + prescribed information | G7: =IF(F7="","",F7-TODAY()) | H7: =IF(B7="","",IF(F7="",IF(D7="","Missing","Recorded"),IF(G7<0,"OVERDUE",IF(G7<=60,"Due soon","OK")))) | I7: Protect in a government-approved scheme and give prescribed information within 30 days of receiving it. | J7: gov.uk/deposit-protection-schemes-and-landlords
A8: 1 | B8: =IF(Properties!B2="","",Properties!B2) | C8: Right to Rent check | G8: =IF(F8="","",F8-TODAY()) | H8: =IF(B8="","",IF(F8="",IF(D8="","Missing","Recorded"),IF(G8<0,"OVERDUE",IF(G8<=60,"Due soon","OK")))) | I8: Before the tenancy starts; repeat check before a time-limited permission expires. | J8: gov.uk/check-tenant-right-to-rent-documents
A9: 1 | B9: =IF(Properties!B2="","",Properties!B2) | C9: Licence (HMO / selective) expiry | F9: =IF(D9="","",D9) | G9: =IF(F9="","",F9-TODAY()) | H9: =IF(B9="","",IF(F9="",IF(D9="","Missing","Recorded"),IF(G9<0,"OVERDUE",IF(G9<=60,"Due soon","OK")))) | I9: If your council requires a licence, enter its expiry date. Licences usually last up to 5 years. | J9: gov.uk/house-in-multiple-occupation-licence
A10: 1 | B10: =IF(Properties!B2="","",Properties!B2) | C10: Landlord insurance renewal | E10: 12 | F10: =IF(D10="","",EDATE(D10,E10)) | G10: =IF(F10="","",F10-TODAY()) | H10: =IF(B10="","",IF(F10="",IF(D10="","Missing","Recorded"),IF(G10<0,"OVERDUE",IF(G10<=60,"Due soon","OK")))) | I10: Your policy renewal date.
A11: 1 | B11: =IF(Properties!B2="","",Properties!B2) | C11: Legionella risk assessment review | G11: =IF(F11="","",F11-TODAY()) | H11: =IF(B11="","",IF(F11="",IF(D11="","Missing","Recorded"),IF(G11<0,"OVERDUE",IF(G11<=60,"Due soon","OK")))) | I11: Landlords must assess legionella risk. The law sets no fixed interval; review when anything changes. | J11: hse.gov.uk/legionnaires/landlords.htm
A12: 2 | B12: =IF(Properties!B3="","",Properties!B3) | C12: Gas safety check (CP12) | E12: 12 | F12: =IF(D12="","",EDATE(D12,E12)) | G12: =IF(F12="","",F12-TODAY()) | H12: =IF(B12="","",IF(F12="",IF(D12="","Missing","Recorded"),IF(G12<0,"OVERDUE",IF(G12<=60,"Due soon","OK")))) | I12: Every 12 months by a Gas Safe engineer; copy to tenants within 28 days; keep records 2 years. | J12: gov.uk/government/publications/gas-safety-landlords-and-tenants
A13: 2 | B13: =IF(Properties!B3="","",Properties!B3) | C13: Electrical safety report (EICR) | E13: 60 | F13: =IF(D13="","",EDATE(D13,E13)) | G13: =IF(F13="","",F13-TODAY()) | H13: =IF(B13="","",IF(F13="",IF(D13="","Missing","Recorded"),IF(G13<0,"OVERDUE",IF(G13<=60,"Due soon","OK")))) | I13: At least every 5 years by a qualified person; copy to tenants within 28 days. | J13: gov.uk/government/publications/electrical-safety-standards-in-the-private-rented-sector-guidance-for-landlords-tenants-and-local-authorities
A14: 2 | B14: =IF(Properties!B3="","",Properties!B3) | C14: Energy Performance Certificate (EPC) | E14: 120 | F14: =IF(D14="","",EDATE(D14,E14)) | G14: =IF(F14="","",F14-TODAY()) | H14: =IF(B14="","",IF(F14="",IF(D14="","Missing","Recorded"),IF(G14<0,"OVERDUE",IF(G14<=60,"Due soon","OK")))) | I14: Valid 10 years; rating must be E or above to let (unless exempt). | J14: gov.uk/guidance/domestic-private-rented-property-minimum-energy-efficiency-standard-landlord-guidance
A15: 2 | B15: =IF(Properties!B3="","",Properties!B3) | C15: Smoke alarms tested | G15: =IF(F15="","",F15-TODAY()) | H15: =IF(B15="","",IF(F15="",IF(D15="","Missing","Recorded"),IF(G15<0,"OVERDUE",IF(G15<=60,"Due soon","OK")))) | I15: At least one on every storey used as living accommodation; check working on the first day of each tenancy. | J15: gov.uk/government/publications/smoke-and-carbon-monoxide-alarms-explanatory-booklet-for-landlords
A16: 2 | B16: =IF(Properties!B3="","",Properties!B3) | C16: Carbon monoxide alarms tested | G16: =IF(F16="","",F16-TODAY()) | H16: =IF(B16="","",IF(F16="",IF(D16="","Missing","Recorded"),IF(G16<0,"OVERDUE",IF(G16<=60,"Due soon","OK")))) | I16: In any room with a fixed combustion appliance (not gas cookers); check on the first day of each tenancy. | J16: gov.uk/government/publications/smoke-and-carbon-monoxide-alarms-explanatory-booklet-for-landlords
A17: 2 | B17: =IF(Properties!B3="","",Properties!B3) | C17: Deposit protected + prescribed information | G17: =IF(F17="","",F17-TODAY()) | H17: =IF(B17="","",IF(F17="",IF(D17="","Missing","Recorded"),IF(G17<0,"OVERDUE",IF(G17<=60,"Due soon","OK")))) | I17: Protect in a government-approved scheme and give prescribed information within 30 days of receiving it. | J17: gov.uk/deposit-protection-schemes-and-landlords
A18: 2 | B18: =IF(Properties!B3="","",Properties!B3) | C18: Right to Rent check | G18: =IF(F18="","",F18-TODAY()) | H18: =IF(B18="","",IF(F18="",IF(D18="","Missing","Recorded"),IF(G18<0,"OVERDUE",IF(G18<=60,"Due soon","OK")))) | I18: Before the tenancy starts; repeat check before a time-limited permission expires. | J18: gov.uk/check-tenant-right-to-rent-documents
A19: 2 | B19: =IF(Properties!B3="","",Properties!B3) | C19: Licence (HMO / selective) expiry | F19: =IF(D19="","",D19) | G19: =IF(F19="","",F19-TODAY()) | H19: =IF(B19="","",IF(F19="",IF(D19="","Missing","Recorded"),IF(G19<0,"OVERDUE",IF(G19<=60,"Due soon","OK")))) | I19: If your council requires a licence, enter its expiry date. Licences usually last up to 5 years. | J19: gov.uk/house-in-multiple-occupation-licence
A20: 2 | B20: =IF(Properties!B3="","",Properties!B3) | C20: Landlord insurance renewal | E20: 12 | F20: =IF(D20="","",EDATE(D20,E20)) | G20: =IF(F20="","",F20-TODAY()) | H20: =IF(B20="","",IF(F20="",IF(D20="","Missing","Recorded"),IF(G20<0,"OVERDUE",IF(G20<=60,"Due soon","OK")))) | I20: Your policy renewal date.
A21: 2 | B21: =IF(Properties!B3="","",Properties!B3) | C21: Legionella risk assessment review | G21: =IF(F21="","",F21-TODAY()) | H21: =IF(B21="","",IF(F21="",IF(D21="","Missing","Recorded"),IF(G21<0,"OVERDUE",IF(G21<=60,"Due soon","OK")))) | I21: Landlords must assess legionella risk. The law sets no fixed interval; review when anything changes. | J21: hse.gov.uk/legionnaires/landlords.htm
A22: 3 | B22: =IF(Properties!B4="","",Properties!B4) | C22: Gas safety check (CP12) | E22: 12 | F22: =IF(D22="","",EDATE(D22,E22)) | G22: =IF(F22="","",F22-TODAY()) | H22: =IF(B22="","",IF(F22="",IF(D22="","Missing","Recorded"),IF(G22<0,"OVERDUE",IF(G22<=60,"Due soon","OK")))) | I22: Every 12 months by a Gas Safe engineer; copy to tenants within 28 days; keep records 2 years. | J22: gov.uk/government/publications/gas-safety-landlords-and-tenants
A23: 3 | B23: =IF(Properties!B4="","",Properties!B4) | C23: Electrical safety report (EICR) | E23: 60 | F23: =IF(D23="","",EDATE(D23,E23)) | G23: =IF(F23="","",F23-TODAY()) | H23: =IF(B23="","",IF(F23="",IF(D23="","Missing","Recorded"),IF(G23<0,"OVERDUE",IF(G23<=60,"Due soon","OK")))) | I23: At least every 5 years by a qualified person; copy to tenants within 28 days. | J23: gov.uk/government/publications/electrical-safety-standards-in-the-private-rented-sector-guidance-for-landlords-tenants-and-local-authorities
A24: 3 | B24: =IF(Properties!B4="","",Properties!B4) | C24: Energy Performance Certificate (EPC) | E24: 120 | F24: =IF(D24="","",EDATE(D24,E24)) | G24: =IF(F24="","",F24-TODAY()) | H24: =IF(B24="","",IF(F24="",IF(D24="","Missing","Recorded"),IF(G24<0,"OVERDUE",IF(G24<=60,"Due soon","OK")))) | I24: Valid 10 years; rating must be E or above to let (unless exempt). | J24: gov.uk/guidance/domestic-private-rented-property-minimum-energy-efficiency-standard-landlord-guidance
A25: 3 | B25: =IF(Properties!B4="","",Properties!B4) | C25: Smoke alarms tested | G25: =IF(F25="","",F25-TODAY()) | H25: =IF(B25="","",IF(F25="",IF(D25="","Missing","Recorded"),IF(G25<0,"OVERDUE",IF(G25<=60,"Due soon","OK")))) | I25: At least one on every storey used as living accommodation; check working on the first day of each tenancy. | J25: gov.uk/government/publications/smoke-and-carbon-monoxide-alarms-explanatory-booklet-for-landlords
A26: 3 | B26: =IF(Properties!B4="","",Properties!B4) | C26: Carbon monoxide alarms tested | G26: =IF(F26="","",F26-TODAY()) | H26: =IF(B26="","",IF(F26="",IF(D26="","Missing","Recorded"),IF(G26<0,"OVERDUE",IF(G26<=60,"Due soon","OK")))) | I26: In any room with a fixed combustion appliance (not gas cookers); check on the first day of each tenancy. | J26: gov.uk/government/publications/smoke-and-carbon-monoxide-alarms-explanatory-booklet-for-landlords
A27: 3 | B27: =IF(Properties!B4="","",Properties!B4) | C27: Deposit protected + prescribed information | G27: =IF(F27="","",F27-TODAY()) | H27: =IF(B27="","",IF(F27="",IF(D27="","Missing","Recorded"),IF(G27<0,"OVERDUE",IF(G27<=60,"Due soon","OK")))) | I27: Protect in a government-approved scheme and give prescribed information within 30 days of receiving it. | J27: gov.uk/deposit-protection-schemes-and-landlords
A28: 3 | B28: =IF(Properties!B4="","",Properties!B4) | C28: Right to Rent check | G28: =IF(F28="","",F28-TODAY()) | H28: =IF(B28="","",IF(F28="",IF(D28="","Missing","Recorded"),IF(G28<0,"OVERDUE",IF(G28<=60,"Due soon","OK")))) | I28: Before the tenancy starts; repeat check before a time-limited permission expires. | J28: gov.uk/check-tenant-right-to-rent-documents
A29: 3 | B29: =IF(Properties!B4="","",Properties!B4) | C29: Licence (HMO / selective) expiry | F29: =IF(D29="","",D29) | G29: =IF(F29="","",F29-TODAY()) | H29: =IF(B29="","",IF(F29="",IF(D29="","Missing","Recorded"),IF(G29<0,"OVERDUE",IF(G29<=60,"Due soon","OK")))) | I29: If your council requires a licence, enter its expiry date. Licences usually last up to 5 years. | J29: gov.uk/house-in-multiple-occupation-licence
A30: 3 | B30: =IF(Properties!B4="","",Properties!B4) | C30: Landlord insurance renewal | E30: 12 | F30: =IF(D30="","",EDATE(D30,E30)) | G30: =IF(F30="","",F30-TODAY()) | H30: =IF(B30="","",IF(F30="",IF(D30="","Missing","Recorded"),IF(G30<0,"OVERDUE",IF(G30<=60,"Due soon","OK")))) | I30: Your policy renewal date.
A31: 3 | B31: =IF(Properties!B4="","",Properties!B4) | C31: Legionella risk assessment review | G31: =IF(F31="","",F31-TODAY()) | H31: =IF(B31="","",IF(F31="",IF(D31="","Missing","Recorded"),IF(G31<0,"OVERDUE",IF(G31<=60,"Due soon","OK")))) | I31: Landlords must assess legionella risk. The law sets no fixed interval; review when anything changes. | J31: hse.gov.uk/legionnaires/landlords.htm
A32: 4 | B32: =IF(Properties!B5="","",Properties!B5) | C32: Gas safety check (CP12) | E32: 12 | F32: =IF(D32="","",EDATE(D32,E32)) | G32: =IF(F32="","",F32-TODAY()) | H32: =IF(B32="","",IF(F32="",IF(D32="","Missing","Recorded"),IF(G32<0,"OVERDUE",IF(G32<=60,"Due soon","OK")))) | I32: Every 12 months by a Gas Safe engineer; copy to tenants within 28 days; keep records 2 years. | J32: gov.uk/government/publications/gas-safety-landlords-and-tenants
A33: 4 | B33: =IF(Properties!B5="","",Properties!B5) | C33: Electrical safety report (EICR) | E33: 60 | F33: =IF(D33="","",EDATE(D33,E33)) | G33: =IF(F33="","",F33-TODAY()) | H33: =IF(B33="","",IF(F33="",IF(D33="","Missing","Recorded"),IF(G33<0,"OVERDUE",IF(G33<=60,"Due soon","OK")))) | I33: At least every 5 years by a qualified person; copy to tenants within 28 days. | J33: gov.uk/government/publications/electrical-safety-standards-in-the-private-rented-sector-guidance-for-landlords-tenants-and-local-authorities
A34: 4 | B34: =IF(Properties!B5="","",Properties!B5) | C34: Energy Performance Certificate (EPC) | E34: 120 | F34: =IF(D34="","",EDATE(D34,E34)) | G34: =IF(F34="","",F34-TODAY()) | H34: =IF(B34="","",IF(F34="",IF(D34="","Missing","Recorded"),IF(G34<0,"OVERDUE",IF(G34<=60,"Due soon","OK")))) | I34: Valid 10 years; rating must be E or above to let (unless exempt). | J34: gov.uk/guidance/domestic-private-rented-property-minimum-energy-efficiency-standard-landlord-guidance
A35: 4 | B35: =IF(Properties!B5="","",Properties!B5) | C35: Smoke alarms tested | G35: =IF(F35="","",F35-TODAY()) | H35: =IF(B35="","",IF(F35="",IF(D35="","Missing","Recorded"),IF(G35<0,"OVERDUE",IF(G35<=60,"Due soon","OK")))) | I35: At least one on every storey used as living accommodation; check working on the first day of each tenancy. | J35: gov.uk/government/publications/smoke-and-carbon-monoxide-alarms-explanatory-booklet-for-landlords
A36: 4 | B36: =IF(Properties!B5="","",Properties!B5) | C36: Carbon monoxide alarms tested | G36: =IF(F36="","",F36-TODAY()) | H36: =IF(B36="","",IF(F36="",IF(D36="","Missing","Recorded"),IF(G36<0,"OVERDUE",IF(G36<=60,"Due soon","OK")))) | I36: In any room with a fixed combustion appliance (not gas cookers); check on the first day of each tenancy. | J36: gov.uk/government/publications/smoke-and-carbon-monoxide-alarms-explanatory-booklet-for-landlords
A37: 4 | B37: =IF(Properties!B5="","",Properties!B5) | C37: Deposit protected + prescribed information | G37: =IF(F37="","",F37-TODAY()) | H37: =IF(B37="","",IF(F37="",IF(D37="","Missing","Recorded"),IF(G37<0,"OVERDUE",IF(G37<=60,"Due soon","OK")))) | I37: Protect in a government-approved scheme and give prescribed information within 30 days of receiving it. | J37: gov.uk/deposit-protection-schemes-and-landlords
A38: 4 | B38: =IF(Properties!B5="","",Properties!B5) | C38: Right to Rent check | G38: =IF(F38="","",F38-TODAY()) | H38: =IF(B38="","",IF(F38="",IF(D38="","Missing","Recorded"),IF(G38<0,"OVERDUE",IF(G38<=60,"Due soon","OK")))) | I38: Before the tenancy starts; repeat check before a time-limited permission expires. | J38: gov.uk/check-tenant-right-to-rent-documents
A39: 4 | B39: =IF(Properties!B5="","",Properties!B5) | C39: Licence (HMO / selective) expiry | F39: =IF(D39="","",D39) | G39: =IF(F39="","",F39-TODAY()) | H39: =IF(B39="","",IF(F39="",IF(D39="","Missing","Recorded"),IF(G39<0,"OVERDUE",IF(G39<=60,"Due soon","OK")))) | I39: If your council requires a licence, enter its expiry date. Licences usually last up to 5 years. | J39: gov.uk/house-in-multiple-occupation-licence
A40: 4 | B40: =IF(Properties!B5="","",Properties!B5) | C40: Landlord insurance renewal | E40: 12 | F40: =IF(D40="","",EDATE(D40,E40)) | G40: =IF(F40="","",F40-TODAY()) | H40: =IF(B40="","",IF(F40="",IF(D40="","Missing","Recorded"),IF(G40<0,"OVERDUE",IF(G40<=60,"Due soon","OK")))) | I40: Your policy renewal date.
...

Sheet Renters' Rights Act
A1: When / topic | B1: What it means for you | C1: Done? | D1: Source
A2: 1 May 2026 | B2: Fixed-term assured shorthold tenancies became assured periodic tenancies. Section 21 'no fault' evictions ended; possession now only via Section 8 grounds. | D2: legislation.gov.uk/uksi/2026/421/made
A3: 31 May 2026 | B3: Existing written tenancies: give every named tenant the government's 'Renters' Rights Act Information Sheet 2026' (exact gov.uk PDF). Fine up to £7,000 if not given. | D3: gov.uk (search 'Renters' Rights Act Information Sheet 2026')
A4: New tenancies from 1 May 2026 | B4: Provide a written statement of terms before the tenancy starts. | D4: gov.uk/guidance/renters-rights-act-2025
A5: Rent increases | B5: Only once a year, using the Section 13 notice procedure; tenants can challenge at tribunal. | D5: gov.uk/guidance/renters-rights-act-2025
A6: Pets | B6: Tenants can ask to keep a pet; you must not unreasonably refuse and must reply in writing. | D6: gov.uk/guidance/renters-rights-act-2025
A7: Discrimination | B7: Must not refuse tenants because they have children or receive benefits. | D7: gov.uk/guidance/renters-rights-act-2025
A8: Rental bidding | B8: Must advertise a rent and not accept offers above it. | D8: gov.uk/guidance/renters-rights-act-2025
A9: Later phases | B9: Private Rented Sector Database registration, Landlord Ombudsman membership and Decent Homes Standard - dates to be confirmed by government. Check before letting. | D9: gov.uk/guidance/renters-rights-act-2025
A11: For landlords letting in England. A record-keeping aid, not legal advice. Rules differ in Wales, Scotland and Northern Ireland. Always check the linked gov.uk source; rules change.
